<?xml version="1.0"?>
<sdf version="1.6">
    <model name="CafeRobot">
        <plugin name="slotcar" filename="libslotcar.so">

            <nominal_drive_speed>0.5</nominal_drive_speed>
            <nominal_drive_acceleration>0.25</nominal_drive_acceleration>
            <max_drive_acceleration>0.75</max_drive_acceleration>

            <nominal_turn_speed>0.6</nominal_turn_speed>
            <nominal_turn_acceleration>1.5</nominal_turn_acceleration>
            <max_turn_acceleration>2.0</max_turn_acceleration>

            <tire_radius>0.1</tire_radius>
            <base_width>0.3206</base_width>

            <stop_distance>0.35</stop_distance>
            <stop_radius>0.35</stop_radius>

        </plugin>

        <pose>0 0 0.063494 0 0 0</pose>
        <enable_wind>1</enable_wind>
        <link name="base_link">
            <inertial>
                <pose>0.011999 0.002 0.066996 0 -0 0</pose>
                <mass>16.524</mass>
                <inertia>
                    <ixx>0.320605</ixx>
                    <ixy>-0.000800023</ixy>
                    <ixz>0.0163992</ixz>
                    <iyy>0.399205</iyy>
                    <iyz>-0.000900133</iyz>
                    <izz>0.455501</izz>
                </inertia>
            </inertial>
            <collision name="chassis_collision">
                <pose>0 0 0.092 0 -0 0</pose>
                <geometry>
                    <box>
                        <size>0.42 0.31 0.184</size>
                    </box>
                </geometry>
            </collision>
            <visual name="chassis_visual">
                <pose>0 0 -0.0655 1.5708 0 -1.5708</pose>
                <geometry>
                    <mesh>
                        <uri>model://CafeRobot/meshes/CafeRobot_chassis.dae</uri>
                    </mesh>
                </geometry>
            </visual>
            <visual name="navsat_visual_1">
                <pose>-0.18 0.126 0.1895 0 -0 0</pose>
                <geometry>
                    <cylinder>
                        <length>0.016</length>
                        <radius>0.026</radius>
                    </cylinder>
                </geometry>
            </visual>

            <visual name="camera_left_visual">
                <pose>0.23 0.1 0.19 0 0 0</pose>
                <geometry>
                    <box>
                        <size>0.02 0.02 0.02</size>
                    </box>
                </geometry>
            </visual>

            <visual name="camera_right_visual">
                <pose>0.23 -0.1 0.19 0 0 0</pose>
                <geometry>
                    <box>
                        <size>0.02 0.02 0.02</size>
                    </box>
                </geometry>
            </visual>

        </link>

        <link name="front_left_wheel">
            <pose>0.131 0.187795 0.0345 0 -0 0</pose>
            <inertial>
                <mass>0.477</mass>
                <inertia>
                    <ixx>0.0013</ixx>
                    <ixy>0</ixy>
                    <ixz>0</ixz>
                    <iyy>0.0024</iyy>
                    <iyz>0</iyz>
                    <izz>0.0013</izz>
                </inertia>
            </inertial>
            <collision name="collision">
                <pose>0 0 0 1.5707963267948966 -0 0</pose>
                <geometry>
                    <cylinder>
                        <length>0.04</length>
                        <radius>0.098</radius>
                    </cylinder>
                </geometry>
                <surface>
                  <friction>
                    <ode>
                      <mu>1</mu>
                      <mu2>1</mu2>
                      <slip1>0.0475</slip1>
                      <slip2>0</slip2>
                      <fdir1>0 0 1</fdir1>
                    </ode>
                  </friction>
                </surface>
            </collision>
            <visual name="visual">
                <pose>0 0 0 1.5708 -0 0</pose>
                <geometry>
                    <mesh>
                        <uri>model://CafeRobot/meshes/CafeRobot_wheel_left.dae</uri>
                    </mesh>
                </geometry>
            </visual>
        </link>

        <link name="front_right_wheel">
            <pose>0.131 -0.187795 0.0345 0 -0 0</pose>
            <inertial>
                <mass>0.477</mass>
                <inertia>
                    <ixx>0.0013</ixx>
                    <ixy>0</ixy>
                    <ixz>0</ixz>
                    <iyy>0.0024</iyy>
                    <iyz>0</iyz>
                    <izz>0.0013</izz>
                </inertia>
            </inertial>
            <collision name="collision">
                <pose>0 0 0 1.5707963267948966 -0 0</pose>
                <geometry>
                    <cylinder>
                        <length>0.04</length>
                        <radius>0.098</radius>
                    </cylinder>
                </geometry>
                <surface>
                  <friction>
                    <ode>
                      <mu>1</mu>
                      <mu2>1</mu2>
                      <slip1>0.0475</slip1>
                      <slip2>0</slip2>
                      <fdir1>0 0 1</fdir1>
                    </ode>
                  </friction>
                </surface>
            </collision>
            <visual name="visual">
                <pose>0 0 0 1.5708 -0 0</pose>
                <geometry>
                    <mesh>
                        <uri>model://CafeRobot/meshes/CafeRobot_wheel_right.dae</uri>
                    </mesh>
                </geometry>
            </visual>
        </link>

        <link name="rear_left_wheel">
            <pose>-0.131 0.187795 0.0345 0 -0 0</pose>
            <inertial>
                <mass>0.477</mass>
                <inertia>
                    <ixx>0.0013</ixx>
                    <ixy>0</ixy>
                    <ixz>0</ixz>
                    <iyy>0.0024</iyy>
                    <iyz>0</iyz>
                    <izz>0.0013</izz>
                </inertia>
            </inertial>
            <collision name="collision">
                <pose>0 0 0 1.5707963267948966 -0 0</pose>
                <geometry>
                    <cylinder>
                        <length>0.04</length>
                        <radius>0.098</radius>
                    </cylinder>
                </geometry>
                <surface>
                  <friction>
                    <ode>
                      <mu>1</mu>
                      <mu2>1</mu2>
                      <slip1>0.0475</slip1>
                      <slip2>0</slip2>
                      <fdir1>0 0 1</fdir1>
                    </ode>
                  </friction>
                </surface>
            </collision>
            <visual name="visual">
                <pose>0 0 0 1.5708 -0 0</pose>
                <geometry>
                    <mesh>
                        <uri>model://CafeRobot/meshes/CafeRobot_wheel_left.dae</uri>
                    </mesh>
                </geometry>
            </visual>
        </link>

        <link name="rear_right_wheel">
            <pose>-0.131 -0.187795 0.0345 0 -0 0</pose>
            <inertial>
                <mass>0.477</mass>
                <inertia>
                    <ixx>0.0013</ixx>
                    <ixy>0</ixy>
                    <ixz>0</ixz>
                    <iyy>0.0024</iyy>
                    <iyz>0</iyz>
                    <izz>0.0013</izz>
                </inertia>
            </inertial>
            <collision name="collision">
                <pose>0 0 0 1.5707963267948966 -0 0</pose>
                <geometry>
                    <cylinder>
                        <length>0.04</length>
                        <radius>0.098</radius>
                    </cylinder>
                </geometry>
                <surface>
                  <friction>
                    <ode>
                      <mu>1</mu>
                      <mu2>1</mu2>
                      <slip1>0.0475</slip1>
                      <slip2>0</slip2>
                      <fdir1>0 0 1</fdir1>
                    </ode>
                  </friction>
                </surface>
            </collision>
            <visual name="visual">
                <pose>0 0 0 1.5708 -0 0</pose>
                <geometry>
                    <mesh>
                        <uri>model://CafeRobot/meshes/CafeRobot_wheel_right.dae</uri>
                    </mesh>
                </geometry>
            </visual>
        </link>

        <joint name="front_left_wheel_joint" type="revolute">
            <child>front_left_wheel</child>
            <parent>base_link</parent>
            <axis>
                <xyz>0 1 0</xyz>
                <limit>
                    <lower>-1e+16</lower>
                    <upper>1e+16</upper>
                </limit>
                <use_parent_model_frame>1</use_parent_model_frame>
            </axis>
        </joint>

        <joint name="joint_tire_left" type="revolute">
            <parent>base_link</parent>
            <child>rear_left_wheel</child>
            <axis>
                <xyz>0 1 0</xyz>
                <limit>
                    <lower>-1.79769e+308</lower>
                    <upper>+1.79769e+308</upper>
                </limit>
            </axis>
        </joint>

        <joint name="joint_tire_right" type="revolute">
            <parent>base_link</parent>
            <child>rear_right_wheel</child>
            <axis>
                <xyz>0 1 0</xyz>
                <limit>
                    <lower>-1.79769e+308</lower>
                    <upper>+1.79769e+308</upper>
                </limit>
            </axis>
        </joint>

        <joint name="front_right_wheel_joint" type="revolute">
            <parent>base_link</parent>
            <child>front_right_wheel</child>
            <axis>
                <xyz>0 1 0</xyz>
                <limit>
                    <lower>-1.79769e+308</lower>
                    <upper>+1.79769e+308</upper>
                </limit>
            </axis>
        </joint>
    </model>
</sdf>
