<sdf version='1.6'>
  <model name='2WD_rover_robotics'>
    <link name='base_footprint'>
      <pose frame=''>0 0 0 0 -0 0</pose>
      <inertial>
        <pose frame=''>-0.151308 0 0.144308 0 -0 0</pose>
        <mass>9.65</mass>
        <inertia>
          <ixx>0.091747</ixx>
          <ixy>2.64698e-23</ixy>
          <ixz>-0.00888848</ixz>
          <iyy>0.18812</iyy>
          <iyz>0</iyz>
          <izz>0.199045</izz>
        </inertia>
      </inertial>
      <collision name='base_footprint_fixed_joint_lump__base_link_collision'>
        <pose frame=''>-0.142 0 0.12 0 -0 0</pose>
        <geometry>
          <box>
            <size>0.42 0.25 0.12</size>
          </box>
        </geometry>
        <surface>
          <contact>
            <ode/>
          </contact>
          <friction>
            <ode/>
          </friction>
        </surface>
      </collision>
      <collision name='base_footprint_fixed_joint_lump__sheetmetal_link_collision_1'>
        <pose frame=''>-0.357 0 0.12 0 -0 0</pose>
        <geometry>
          <box>
            <size>0.065 0.4 0.008</size>
          </box>
        </geometry>
        <surface>
          <contact>
            <ode/>
          </contact>
          <friction>
            <ode/>
          </friction>
        </surface>
      </collision>
      <visual name='base_footprint_fixed_joint_lump__base_link_visual'>
        <pose frame=''>-0.142 0 0.175 0 -0 1.57</pose>
        <geometry>
          <mesh>
            <scale>1 1 1</scale>
            <uri>model://2WDRover/meshes/2WD_OpenRover.stl</uri>
          </mesh>
        </geometry>
        <material>
          <script>
            <name>Gazebo/FlatBlack</name>
            <uri>file://media/materials/scripts/gazebo.material</uri>
          </script>
        </material>
      </visual>
      <visual name='base_footprint_fixed_joint_lump__plate_link_visual_1'>
        <pose frame=''>-0.1365 0 0.247 0 -0 0</pose>
        <geometry>
          <box>
            <size>0.381 0.254 0.005</size>
          </box>
        </geometry>
        <material>
          <script>
            <name>Gazebo/GreyTransparent</name>
            <uri>file://media/materials/scripts/gazebo.material</uri>
          </script>
        </material>
      </visual>
      <visual name='base_footprint_fixed_joint_lump__cpu_link_visual_2'>
        <pose frame=''>-0.1397 0 0.2745 0 -0 0</pose>
        <geometry>
          <box>
            <size>0.111 0.117 0.05</size>
          </box>
        </geometry>
        <material>
          <script>
            <name>Gazebo/DarkGrey</name>
            <uri>file://media/materials/scripts/gazebo.material</uri>
          </script>
        </material>
      </visual>
      <visual name='base_footprint_fixed_joint_lump__lidar_link_visual_3'>
        <pose frame=''>-0.03175 0 0.338 0 -0 3.14</pose>
        <geometry>
          <cylinder>
            <length>0.0476</length>
            <radius>0.0381</radius>
          </cylinder>
        </geometry>
        <material>
          <script>
            <name>Gazebo/DarkGrey</name>
            <uri>file://media/materials/scripts/gazebo.material</uri>
          </script>
        </material>
      </visual>
      <visual name='base_footprint_fixed_joint_lump__imu_link_visual_4'>
        <pose frame=''>0 0 0.2496 0 -0 0</pose>
        <geometry>
          <box>
            <size>0.01 0.01 0.002</size>
          </box>
        </geometry>
        <material>
          <script>
            <name>Gazebo/Blue</name>
            <uri>file://media/materials/scripts/gazebo.material</uri>
          </script>
        </material>
      </visual>
      <visual name='base_footprint_fixed_joint_lump__sheetmetal_link_visual_5'>
        <pose frame=''>-0.35 0 0.12 1.57 0 -1.57</pose>
        <geometry>
          <mesh>
            <scale>1 1 1</scale>
            <uri>model://2WDRover/meshes/sheetmetal_part.stl</uri>
          </mesh>
        </geometry>
        <material>
          <script>
            <name>Gazebo/FlatBlack</name>
            <uri>file://media/materials/scripts/gazebo.material</uri>
          </script>
        </material>
      </visual>
      <velocity_decay/>
      <velocity_decay/>
      <velocity_decay/>
      <velocity_decay/>
      <sensor name='gazebo_lidar' type='ray'>
        <update_rate>12</update_rate>
        <plugin name='gazebo_lidar' filename='libgazebo_ros_ray_sensor.so'>
          <ros>
            <argument>~/out:=scan</argument>
            <namespace/>
          </ros>
          <output_type>sensor_msgs/LaserScan</output_type>
          <frame_name>lidar_link</frame_name>
        </plugin>
        <ray>
          <scan>
            <horizontal>
              <samples>360</samples>
              <resolution>1</resolution>
              <min_angle>-3.14159</min_angle>
              <max_angle>3.14159</max_angle>
            </horizontal>
          </scan>
          <range>
            <min>0.12</min>
            <max>3.5</max>
            <resolution>0.015</resolution>
          </range>
          <noise>
            <type>gaussian</type>
            <mean>0</mean>
            <stddev>0.01</stddev>
          </noise>
        </ray>
        <pose frame=''>-0.03175 0 0.338 0 -0 3.14</pose>
      </sensor>
      <velocity_decay/>
      <sensor name='gazebo_imu' type='imu'>
        <always_on>1</always_on>
        <update_rate>30</update_rate>
        <plugin name='gazebo_imu' filename='libgazebo_ros_imu_sensor.so'>
          <ros>
            <namespace>/imu</namespace>
            <argument>~/out:=data</argument>
          </ros>
          <frame_name>imu_link</frame_name>
        </plugin>
        <imu>
          <angular_velocity>
            <x>
              <noise type='gaussian'>
                <mean>0</mean>
                <stddev>0.0052</stddev>
              </noise>
            </x>
            <y>
              <noise type='gaussian'>
                <mean>0</mean>
                <stddev>0.0052</stddev>
              </noise>
            </y>
            <z>
              <noise type='gaussian'>
                <mean>0</mean>
                <stddev>0.0052</stddev>
              </noise>
            </z>
          </angular_velocity>
          <linear_acceleration>
            <x>
              <noise type='gaussian'>
                <mean>0</mean>
                <stddev>0.0015</stddev>
              </noise>
            </x>
            <y>
              <noise type='gaussian'>
                <mean>0</mean>
                <stddev>0.0015</stddev>
              </noise>
            </y>
            <z>
              <noise type='gaussian'>
                <mean>0</mean>
                <stddev>0.0015</stddev>
              </noise>
            </z>
          </linear_acceleration>
          <angular_velocity/>
          <linear_acceleration/>
        </imu>
        <pose frame=''>0 0 0.2496 0 -0 0</pose>
      </sensor>
      <gravity>1</gravity>
      <velocity_decay/>
    </link>
    <link name='caster_back_left_link'>
      <pose frame=''>-0.36 0.17 0.11 0 -0 0</pose>
      <inertial>
        <pose frame=''>-0.005 0 -0.03 0 -0 0</pose>
        <mass>0.41</mass>
        <inertia>
          <ixx>0.0003841</ixx>
          <ixy>0</ixy>
          <ixz>0</ixz>
          <iyy>0.0004592</iyy>
          <iyz>0</iyz>
          <izz>0.0002135</izz>
        </inertia>
      </inertial>
      <collision name='caster_back_left_link_collision'>
        <pose frame=''>-0.035 0 -0.065 1.57 0 3.14</pose>
        <geometry>
          <cylinder>
            <length>0.0035</length>
            <radius>0.05</radius>
          </cylinder>
        </geometry>
        <surface>
          <contact>
            <ode>
              <kp>200000</kp>
            </ode>
          </contact>
          <friction>
            <ode>
              <mu>0.1</mu>
              <mu2>0.6</mu2>
            </ode>
          </friction>
        </surface>
      </collision>
      <visual name='caster_back_left_link_visual'>
        <pose frame=''>0 0 0 1.57 0 3.14</pose>
        <geometry>
          <mesh>
            <scale>1 1 1</scale>
            <uri>model://2WDRover/meshes/left_caster_wheel.stl</uri>
          </mesh>
        </geometry>
        <material>
          <script>
            <name>Gazebo/Grey</name>
            <uri>file://media/materials/scripts/gazebo.material</uri>
          </script>
        </material>
      </visual>
      <gravity>1</gravity>
      <velocity_decay/>
    </link>
    <joint name='caster_back_left_joint' type='revolute'>
      <child>caster_back_left_link</child>
      <parent>base_footprint</parent>
      <axis>
        <xyz>0 0 1</xyz>
        <limit>
          <lower>-1e+16</lower>
          <upper>1e+16</upper>
        </limit>
        <dynamics>
          <damping>0.1</damping>
          <friction>0.01</friction>
          <spring_reference>0</spring_reference>
          <spring_stiffness>0</spring_stiffness>
        </dynamics>
        <use_parent_model_frame>1</use_parent_model_frame>
      </axis>
    </joint>
    <link name='caster_back_right_link'>
      <pose frame=''>-0.36 -0.17 0.11 0 -0 0</pose>
      <inertial>
        <pose frame=''>-0.005 0 -0.03 0 -0 0</pose>
        <mass>0.41</mass>
        <inertia>
          <ixx>0.0003841</ixx>
          <ixy>0</ixy>
          <ixz>0</ixz>
          <iyy>0.0004592</iyy>
          <iyz>0</iyz>
          <izz>0.0002135</izz>
        </inertia>
      </inertial>
      <collision name='caster_back_right_link_collision'>
        <pose frame=''>-0.035 0 -0.065 1.57 0 3.14</pose>
        <geometry>
          <cylinder>
            <length>0.0035</length>
            <radius>0.05</radius>
          </cylinder>
        </geometry>
        <surface>
          <contact>
            <ode>
              <kp>200000</kp>
            </ode>
          </contact>
          <friction>
            <ode>
              <mu>0.1</mu>
              <mu2>0.6</mu2>
            </ode>
          </friction>
        </surface>
      </collision>
      <visual name='caster_back_right_link_visual'>
        <pose frame=''>0 0 0 1.57 0 3.14</pose>
        <geometry>
          <mesh>
            <scale>1 1 1</scale>
            <uri>model://2WDRover/meshes/right_caster_wheel.stl</uri>
          </mesh>
        </geometry>
        <material>
          <script>
            <name>Gazebo/Grey</name>
            <uri>file://media/materials/scripts/gazebo.material</uri>
          </script>
        </material>
      </visual>
      <gravity>1</gravity>
      <velocity_decay/>
    </link>
    <joint name='caster_back_right_joint' type='revolute'>
      <child>caster_back_right_link</child>
      <parent>base_footprint</parent>
      <axis>
        <xyz>0 0 1</xyz>
        <limit>
          <lower>-1e+16</lower>
          <upper>1e+16</upper>
        </limit>
        <dynamics>
          <damping>0.1</damping>
          <friction>0.01</friction>
          <spring_reference>0</spring_reference>
          <spring_stiffness>0</spring_stiffness>
        </dynamics>
        <use_parent_model_frame>1</use_parent_model_frame>
      </axis>
    </joint>
    <link name='wheel_left_link'>
      <pose frame=''>0 0.179 0.12 -1.57 0 0</pose>
      <inertial>
        <pose frame=''>0 0 0 0 -0 3.14</pose>
        <mass>1.525</mass>
        <inertia>
          <ixx>0.006723</ixx>
          <ixy>0</ixy>
          <ixz>0</ixz>
          <iyy>0.006723</iyy>
          <iyz>0</iyz>
          <izz>0.0122</izz>
        </inertia>
      </inertial>
      <collision name='wheel_left_link_collision'>
        <pose frame=''>0 0 0 0 -0 3.14</pose>
        <geometry>
          <cylinder>
            <length>0.07</length>
            <radius>0.12</radius>
          </cylinder>
        </geometry>
        <surface>
          <contact>
            <ode>
              <kp>300000</kp>
            </ode>
          </contact>
          <friction>
            <ode>
              <mu>0.7</mu>
              <mu2>1</mu2>
            </ode>
          </friction>
        </surface>
      </collision>
      <visual name='wheel_left_link_visual'>
        <pose frame=''>0 0 0 -1.57 0 0</pose>
        <geometry>
          <mesh>
            <scale>1 1 1</scale>
            <uri>model://2WDRover/meshes/left_wheel.stl</uri>
          </mesh>
        </geometry>
        <material>
          <script>
            <name>Gazebo/Black</name>
            <uri>file://media/materials/scripts/gazebo.material</uri>
          </script>
        </material>
      </visual>
      <gravity>1</gravity>
      <velocity_decay/>
    </link>
    <joint name='wheel_left_joint' type='revolute'>
      <child>wheel_left_link</child>
      <parent>base_footprint</parent>
      <axis>
        <xyz>0 1 0.000796</xyz>
        <limit>
          <lower>-1e+16</lower>
          <upper>1e+16</upper>
        </limit>
        <dynamics>
          <spring_reference>0</spring_reference>
          <spring_stiffness>0</spring_stiffness>
        </dynamics>
        <use_parent_model_frame>1</use_parent_model_frame>
      </axis>
    </joint>
    <link name='wheel_right_link'>
      <pose frame=''>0 -0.179 0.12 -1.57 0 0</pose>
      <inertial>
        <pose frame=''>0 0 0 0 -0 0</pose>
        <mass>1.525</mass>
        <inertia>
          <ixx>0.006723</ixx>
          <ixy>0</ixy>
          <ixz>0</ixz>
          <iyy>0.006723</iyy>
          <iyz>0</iyz>
          <izz>0.0122</izz>
        </inertia>
      </inertial>
      <collision name='wheel_right_link_collision'>
        <pose frame=''>0 0 0 0 -0 0</pose>
        <geometry>
          <cylinder>
            <length>0.07</length>
            <radius>0.12</radius>
          </cylinder>
        </geometry>
        <surface>
          <contact>
            <ode>
              <kp>300000</kp>
            </ode>
          </contact>
          <friction>
            <ode>
              <mu>0.7</mu>
              <mu2>1</mu2>
            </ode>
          </friction>
        </surface>
      </collision>
      <visual name='wheel_right_link_visual'>
        <pose frame=''>0 0 0 1.57 -0 0</pose>
        <geometry>
          <mesh>
            <scale>1 1 1</scale>
            <uri>model://2WDRover/meshes/right_wheel.stl</uri>
          </mesh>
        </geometry>
        <material>
          <script>
            <name>Gazebo/Black</name>
            <uri>file://media/materials/scripts/gazebo.material</uri>
          </script>
        </material>
      </visual>
      <gravity>1</gravity>
      <velocity_decay/>
    </link>
    <joint name='wheel_right_joint' type='revolute'>
      <child>wheel_right_link</child>
      <parent>base_footprint</parent>
      <axis>
        <xyz>0 1 0.000796</xyz>
        <limit>
          <lower>-1e+16</lower>
          <upper>1e+16</upper>
        </limit>
        <dynamics>
          <spring_reference>0</spring_reference>
          <spring_stiffness>0</spring_stiffness>
        </dynamics>
        <use_parent_model_frame>1</use_parent_model_frame>
      </axis>
    </joint>
    <plugin name='gazebo_base_controller' filename='libgazebo_ros_diff_drive.so'>
      <odometry_frame>odom</odometry_frame>
      <publish_odom>1</publish_odom>
      <publish_odom_tf>0</publish_odom_tf>
      <robot_base_frame>base_footprint</robot_base_frame>
      <publish_wheel_tf>0</publish_wheel_tf>
      <update_rate>15.0</update_rate>
      <left_joint>wheel_left_joint</left_joint>
      <right_joint>wheel_right_joint</right_joint>
      <wheel_separation>0.358</wheel_separation>
      <wheel_diameter>0.24</wheel_diameter>
      <max_wheel_acceleration>0.7</max_wheel_acceleration>
      <max_wheel_torque>8</max_wheel_torque>
      <ros>
        <argument>odom:=odom_raw</argument>
      </ros>
    </plugin>
    <static>0</static>
    <plugin name='gazebo_joint_publisher' filename='libgazebo_ros_joint_state_publisher.so'>
      <joint_name>wheel_left_joint</joint_name>
      <joint_name>wheel_right_joint</joint_name>
      <joint_name>caster_back_left_joint</joint_name>
      <joint_name>caster_back_right_joint</joint_name>
      <update_rate>30.0</update_rate>
    </plugin>
  </model>
</sdf>
